<?xml version="1.0" encoding="UTF-8"?><testsuite name="nosetests" tests="3" errors="3" failures="0" skip="0"><testcase classname="nose.failure.Failure" name="runTest" time="0.001"><error type="builtins.NameError" message="name 'os' is not defined"><![CDATA[Traceback (most recent call last):
  File "/usr/lib/python3.6/unittest/case.py", line 59, in testPartExecutor
    yield
  File "/usr/lib/python3.6/unittest/case.py", line 605, in run
    testMethod()
  File "/home/vagrant/.local/lib/python3.6/site-packages/nose/failure.py", line 39, in runTest
    raise self.exc_val.with_traceback(self.tb)
  File "/home/vagrant/.local/lib/python3.6/site-packages/nose/loader.py", line 418, in loadTestsFromName
    addr.filename, addr.module)
  File "/home/vagrant/.local/lib/python3.6/site-packages/nose/importer.py", line 47, in importFromPath
    return self.importFromDir(dir_path, fqname)
  File "/home/vagrant/.local/lib/python3.6/site-packages/nose/importer.py", line 94, in importFromDir
    mod = load_module(part_fqname, fh, filename, desc)
  File "/usr/lib/python3.6/imp.py", line 245, in load_module
    return load_package(name, filename)
  File "/usr/lib/python3.6/imp.py", line 217, in load_package
    return _load(spec)
  File "<frozen importlib._bootstrap>", line 684, in _load
  File "<frozen importlib._bootstrap>", line 665, in _load_unlocked
  File "<frozen importlib._bootstrap_external>", line 678, in exec_module
  File "<frozen importlib._bootstrap>", line 219, in _call_with_frames_removed
  File "/vagrant/service/__init__.py", line 17, in <module>
    from service import service, models
  File "/vagrant/service/service.py", line 21, in <module>
    from service.models import ShopCart, CartItem, DataValidationError
  File "/vagrant/service/models.py", line 41, in <module>
    DATABASE_URI = os.getenv("DATABASE_URI", "postgres://postgres:postgres@localhost:5432/postgres")
NameError: name 'os' is not defined
]]></error></testcase><testcase classname="nose.failure.Failure" name="runTest" time="0.000"><error type="builtins.NameError" message="name 'os' is not defined"><![CDATA[Traceback (most recent call last):
  File "/usr/lib/python3.6/unittest/case.py", line 59, in testPartExecutor
    yield
  File "/usr/lib/python3.6/unittest/case.py", line 605, in run
    testMethod()
  File "/home/vagrant/.local/lib/python3.6/site-packages/nose/failure.py", line 39, in runTest
    raise self.exc_val.with_traceback(self.tb)
  File "/home/vagrant/.local/lib/python3.6/site-packages/nose/loader.py", line 418, in loadTestsFromName
    addr.filename, addr.module)
  File "/home/vagrant/.local/lib/python3.6/site-packages/nose/importer.py", line 47, in importFromPath
    return self.importFromDir(dir_path, fqname)
  File "/home/vagrant/.local/lib/python3.6/site-packages/nose/importer.py", line 94, in importFromDir
    mod = load_module(part_fqname, fh, filename, desc)
  File "/usr/lib/python3.6/imp.py", line 235, in load_module
    return load_source(name, filename, file)
  File "/usr/lib/python3.6/imp.py", line 172, in load_source
    module = _load(spec)
  File "<frozen importlib._bootstrap>", line 684, in _load
  File "<frozen importlib._bootstrap>", line 665, in _load_unlocked
  File "<frozen importlib._bootstrap_external>", line 678, in exec_module
  File "<frozen importlib._bootstrap>", line 219, in _call_with_frames_removed
  File "/vagrant/tests/test_models.py", line 8, in <module>
    from service import app
  File "/vagrant/service/__init__.py", line 17, in <module>
    from service import service, models
  File "/vagrant/service/service.py", line 21, in <module>
    from service.models import ShopCart, CartItem, DataValidationError
  File "/vagrant/service/models.py", line 41, in <module>
    DATABASE_URI = os.getenv("DATABASE_URI", "postgres://postgres:postgres@localhost:5432/postgres")
NameError: name 'os' is not defined
]]></error></testcase><testcase classname="nose.failure.Failure" name="runTest" time="0.000"><error type="builtins.IndentationError" message="unexpected indent (test_service.py, line 20)"><![CDATA[Traceback (most recent call last):
  File "/usr/lib/python3.6/unittest/case.py", line 59, in testPartExecutor
    yield
  File "/usr/lib/python3.6/unittest/case.py", line 605, in run
    testMethod()
  File "/home/vagrant/.local/lib/python3.6/site-packages/nose/failure.py", line 39, in runTest
    raise self.exc_val.with_traceback(self.tb)
  File "/home/vagrant/.local/lib/python3.6/site-packages/nose/loader.py", line 418, in loadTestsFromName
    addr.filename, addr.module)
  File "/home/vagrant/.local/lib/python3.6/site-packages/nose/importer.py", line 47, in importFromPath
    return self.importFromDir(dir_path, fqname)
  File "/home/vagrant/.local/lib/python3.6/site-packages/nose/importer.py", line 94, in importFromDir
    mod = load_module(part_fqname, fh, filename, desc)
  File "/usr/lib/python3.6/imp.py", line 235, in load_module
    return load_source(name, filename, file)
  File "/usr/lib/python3.6/imp.py", line 172, in load_source
    module = _load(spec)
  File "<frozen importlib._bootstrap>", line 684, in _load
  File "<frozen importlib._bootstrap>", line 665, in _load_unlocked
  File "<frozen importlib._bootstrap_external>", line 674, in exec_module
  File "<frozen importlib._bootstrap_external>", line 781, in get_code
  File "<frozen importlib._bootstrap_external>", line 741, in source_to_code
  File "<frozen importlib._bootstrap>", line 219, in _call_with_frames_removed
  File "/vagrant/tests/test_service.py", line 20
    "DATABASE_URI", "postgres://postgres:postgres@localhost:5432/postgres"
    ^
IndentationError: unexpected indent
]]></error></testcase></testsuite>